<?xml version="1.0" encoding="utf-8"?>
<robot name="ur5e_robot" path="assets/ur5e/dual_ur5e_gripper.urdf">
	<link name="base_fixture_link"></link>
	<link name="base_link"></link>
	<link name="base_link_1"></link>
	<link name="base_link_inertia">
		<visual>
			<geometry>
				<sphere radius="0.090364"></sphere>
			</geometry>
			<origin xyz="2.856034517288207e-06 -1.318630933761596e-06 0.049546308248533205" rpy="0 0 0"></origin>
		</visual>
		<collision>
			<geometry>
				<sphere radius="0.090364"></sphere>
			</geometry>
			<origin xyz="2.856034517288207e-06 -1.318630933761596e-06 0.049546308248533205" rpy="0 0 0"></origin>
		</collision>
		<inertial>
			<mass value="4.0"></mass>
			<origin rpy="0 0 0" xyz="0 0 0"></origin>
			<inertia ixx="0.00443333156" ixy="0.0" ixz="0.0" iyy="0.00443333156" iyz="0.0" izz="0.0072"></inertia>
		</inertial>
	</link>
	<link name="shoulder_link">
		<visual>
			<geometry>
				<sphere radius="0.089842"></sphere>
			</geometry>
			<origin xyz="-2.6528875827789308e-06 -0.006648757576942443 -0.0015136339838504789" rpy="0 0 0"></origin>
		</visual>
		<collision>
			<geometry>
				<sphere radius="0.089842"></sphere>
			</geometry>
			<origin xyz="-2.6528875827789308e-06 -0.006648757576942443 -0.0015136339838504789" rpy="0 0 0"></origin>
		</collision>
		<inertial>
			<mass value="3.7"></mass>
			<origin rpy="0 0 0" xyz="0 0 0"></origin>
			<inertia ixx="0.010267495893" ixy="0.0" ixz="0.0" iyy="0.010267495893" iyz="0.0" izz="0.00666"></inertia>
		</inertial>
	</link>
	<link name="upper_arm_link">
		<visual>
			<geometry>
				<sphere radius="0.094923"></sphere>
			</geometry>
			<origin xyz="-0.29880514530599117 -2.2440966010107567e-05 0.13065568706798558" rpy="0 0 0"></origin>
		</visual>
		<visual>
			<geometry>
				<sphere radius="0.091263"></sphere>
			</geometry>
			<origin xyz="-0.4223871453059912 -2.9440966010107568e-05 0.12900468706798557" rpy="0 0 0"></origin>
		</visual>
		<visual>
			<geometry>
				<sphere radius="0.090758"></sphere>
			</geometry>
			<origin xyz="-0.00871114530599118 5.559033989892433e-06 0.13537768706798559" rpy="0 0 0"></origin>
		</visual>
		<visual>
			<geometry>
				<sphere radius="0.093838"></sphere>
			</geometry>
			<origin xyz="-0.3703041453059912 -2.5440966010107566e-05 0.13160568706798556" rpy="0 0 0"></origin>
		</visual>
		<visual>
			<geometry>
				<sphere radius="0.092897"></sphere>
			</geometry>
			<origin xyz="-0.08795214530599117 -3.440966010107567e-06 0.13541968706798557" rpy="0 0 0"></origin>
		</visual>
		<visual>
			<geometry>
				<sphere radius="0.093117"></sphere>
			</geometry>
			<origin xyz="-0.22120814530599117 -1.6440966010107567e-05 0.13292768706798558" rpy="0 0 0"></origin>
		</visual>
		<visual>
			<geometry>
				<sphere radius="0.089958"></sphere>
			</geometry>
			<origin xyz="-0.15866314530599118 -1.2440966010107567e-05 0.1317986870679856" rpy="0 0 0"></origin>
		</visual>
		<collision>
			<geometry>
				<sphere radius="0.094923"></sphere>
			</geometry>
			<origin xyz="-0.29880514530599117 -2.2440966010107567e-05 0.13065568706798558" rpy="0 0 0"></origin>
		</collision>
		<collision>
			<geometry>
				<sphere radius="0.091263"></sphere>
			</geometry>
			<origin xyz="-0.4223871453059912 -2.9440966010107568e-05 0.12900468706798557" rpy="0 0 0"></origin>
		</collision>
		<collision>
			<geometry>
				<sphere radius="0.090758"></sphere>
			</geometry>
			<origin xyz="-0.00871114530599118 5.559033989892433e-06 0.13537768706798559" rpy="0 0 0"></origin>
		</collision>
		<collision>
			<geometry>
				<sphere radius="0.093838"></sphere>
			</geometry>
			<origin xyz="-0.3703041453059912 -2.5440966010107566e-05 0.13160568706798556" rpy="0 0 0"></origin>
		</collision>
		<collision>
			<geometry>
				<sphere radius="0.092897"></sphere>
			</geometry>
			<origin xyz="-0.08795214530599117 -3.440966010107567e-06 0.13541968706798557" rpy="0 0 0"></origin>
		</collision>
		<collision>
			<geometry>
				<sphere radius="0.093117"></sphere>
			</geometry>
			<origin xyz="-0.22120814530599117 -1.6440966010107567e-05 0.13292768706798558" rpy="0 0 0"></origin>
		</collision>
		<collision>
			<geometry>
				<sphere radius="0.089958"></sphere>
			</geometry>
			<origin xyz="-0.15866314530599118 -1.2440966010107567e-05 0.1317986870679856" rpy="0 0 0"></origin>
		</collision>
		<inertial>
			<mass value="8.393"></mass>
			<origin rpy="0 1.5707963267948966 0" xyz="-0.2125 0.0 0.138"></origin>
			<inertia ixx="0.1338857818623325" ixy="0.0" ixz="0.0" iyy="0.1338857818623325" iyz="0.0" izz="0.0151074"></inertia>
		</inertial>
	</link>
	<link name="forearm_link">
		<visual>
			<geometry>
				<sphere radius="0.069786"></sphere>
			</geometry>
			<origin xyz="-0.3753460292737264 -0.0003035468224589817 -0.011400678107356396" rpy="0 0 0"></origin>
		</visual>
		<visual>
			<geometry>
				<sphere radius="0.073418"></sphere>
			</geometry>
			<origin xyz="-0.3729900292737264 0.0007594531775410182 0.022953321892643604" rpy="0 0 0"></origin>
		</visual>
		<visual>
			<geometry>
				<sphere radius="0.081417"></sphere>
			</geometry>
			<origin xyz="-0.2952910292737264 -0.00041054682245898175 0.009998321892643606" rpy="0 0 0"></origin>
		</visual>
		<visual>
			<geometry>
				<sphere radius="0.085647"></sphere>
			</geometry>
			<origin xyz="-0.21425702927372642 0.0004334531775410182 0.014403321892643605" rpy="0 0 0"></origin>
		</visual>
		<visual>
			<geometry>
				<sphere radius="0.087811"></sphere>
			</geometry>
			<origin xyz="-0.12363302927372641 0.00024745317754101825 0.012469321892643605" rpy="0 0 0"></origin>
		</visual>
		<visual>
			<geometry>
				<sphere radius="0.086674"></sphere>
			</geometry>
			<origin xyz="-0.045100029273726416 0.001873453177541018 0.014119321892643606" rpy="0 0 0"></origin>
		</visual>
		<visual>
			<geometry>
				<sphere radius="0.066154"></sphere>
			</geometry>
			<origin xyz="0.008519970726273585 0.010306453177541018 0.027016321892643604" rpy="0 0 0"></origin>
		</visual>
		<visual>
			<geometry>
				<sphere radius="0.070424"></sphere>
			</geometry>
			<origin xyz="0.007853970726273585 -0.011542546822458982 0.026729321892643605" rpy="0 0 0"></origin>
		</visual>
		<collision>
			<geometry>
				<sphere radius="0.069786"></sphere>
			</geometry>
			<origin xyz="-0.3753460292737264 -0.0003035468224589817 -0.011400678107356396" rpy="0 0 0"></origin>
		</collision>
		<collision>
			<geometry>
				<sphere radius="0.073418"></sphere>
			</geometry>
			<origin xyz="-0.3729900292737264 0.0007594531775410182 0.022953321892643604" rpy="0 0 0"></origin>
		</collision>
		<collision>
			<geometry>
				<sphere radius="0.081417"></sphere>
			</geometry>
			<origin xyz="-0.2952910292737264 -0.00041054682245898175 0.009998321892643606" rpy="0 0 0"></origin>
		</collision>
		<collision>
			<geometry>
				<sphere radius="0.085647"></sphere>
			</geometry>
			<origin xyz="-0.21425702927372642 0.0004334531775410182 0.014403321892643605" rpy="0 0 0"></origin>
		</collision>
		<collision>
			<geometry>
				<sphere radius="0.087811"></sphere>
			</geometry>
			<origin xyz="-0.12363302927372641 0.00024745317754101825 0.012469321892643605" rpy="0 0 0"></origin>
		</collision>
		<collision>
			<geometry>
				<sphere radius="0.086674"></sphere>
			</geometry>
			<origin xyz="-0.045100029273726416 0.001873453177541018 0.014119321892643606" rpy="0 0 0"></origin>
		</collision>
		<collision>
			<geometry>
				<sphere radius="0.066154"></sphere>
			</geometry>
			<origin xyz="0.008519970726273585 0.010306453177541018 0.027016321892643604" rpy="0 0 0"></origin>
		</collision>
		<collision>
			<geometry>
				<sphere radius="0.070424"></sphere>
			</geometry>
			<origin xyz="0.007853970726273585 -0.011542546822458982 0.026729321892643605" rpy="0 0 0"></origin>
		</collision>
		<inertial>
			<mass value="2.275"></mass>
			<origin rpy="0 1.5707963267948966 0" xyz="-0.1961 0.0 0.007"></origin>
			<inertia ixx="0.031209355099586295" ixy="0.0" ixz="0.0" iyy="0.031209355099586295" iyz="0.0" izz="0.004095"></inertia>
		</inertial>
	</link>
	<link name="wrist_1_link">
		<visual>
			<geometry>
				<sphere radius="0.076148"></sphere>
			</geometry>
			<origin xyz="-0.0002693220568518325 -0.002284190456157314 -0.013745301319436354" rpy="0 0 0"></origin>
		</visual>
		<collision>
			<geometry>
				<sphere radius="0.076148"></sphere>
			</geometry>
			<origin xyz="-0.0002693220568518325 -0.002284190456157314 -0.013745301319436354" rpy="0 0 0"></origin>
		</collision>
		<inertial>
			<mass value="1.219"></mass>
			<origin rpy="0 0 0" xyz="0 0 0"></origin>
			<inertia ixx="0.0025598989760400002" ixy="0.0" ixz="0.0" iyy="0.0025598989760400002" iyz="0.0" izz="0.0021942"></inertia>
		</inertial>
	</link>
	<link name="wrist_2_link">
		<visual>
			<geometry>
				<sphere radius="0.069339"></sphere>
			</geometry>
			<origin xyz="-0.0002282909261638736 0.00045500762583113464 -0.0012575461515493972" rpy="0 0 0"></origin>
		</visual>
		<collision>
			<geometry>
				<sphere radius="0.069339"></sphere>
			</geometry>
			<origin xyz="-0.0002282909261638736 0.00045500762583113464 -0.0012575461515493972" rpy="0 0 0"></origin>
		</collision>
		<inertial>
			<mass value="1.219"></mass>
			<origin rpy="0 0 0" xyz="0 0 0"></origin>
			<inertia ixx="0.0025598989760400002" ixy="0.0" ixz="0.0" iyy="0.0025598989760400002" iyz="0.0" izz="0.0021942"></inertia>
		</inertial>
	</link>
	<link name="wrist_3_link">
		<visual>
			<geometry>
				<sphere radius="0.044717"></sphere>
			</geometry>
			<origin xyz="-0.0002292038618326187 -0.00017992121219634642 -0.022866617411613468" rpy="0 0 0"></origin>
		</visual>
		<collision>
			<geometry>
				<sphere radius="0.044717"></sphere>
			</geometry>
			<origin xyz="-0.0002292038618326187 -0.00017992121219634642 -0.022866617411613468" rpy="0 0 0"></origin>
		</collision>
		<inertial>
			<mass value="0.1879"></mass>
			<origin rpy="0 0 0" xyz="0.0 0.0 -0.0229"></origin>
			<inertia ixx="9.890410052167731e-05" ixy="0.0" ixz="0.0" iyy="9.890410052167731e-05" iyz="0.0" izz="0.0001321171875"></inertia>
		</inertial>
	</link>
	<link name="base"></link>
	<link name="flange"></link>
	<link name="tool0"></link>
	<link name="base_link_inertia_1">
		<visual>
			<geometry>
				<sphere radius="0.090364"></sphere>
			</geometry>
			<origin xyz="2.856034517288207e-06 -1.318630933761596e-06 0.049546308248533205" rpy="0 0 0"></origin>
		</visual>
		<collision>
			<geometry>
				<sphere radius="0.090364"></sphere>
			</geometry>
			<origin xyz="2.856034517288207e-06 -1.318630933761596e-06 0.049546308248533205" rpy="0 0 0"></origin>
		</collision>
		<inertial>
			<mass value="4.0"></mass>
			<origin rpy="0 0 0" xyz="0 0 0"></origin>
			<inertia ixx="0.00443333156" ixy="0.0" ixz="0.0" iyy="0.00443333156" iyz="0.0" izz="0.0072"></inertia>
		</inertial>
	</link>
	<link name="shoulder_link_1">
		<visual>
			<geometry>
				<sphere radius="0.089842"></sphere>
			</geometry>
			<origin xyz="-2.6528875827789308e-06 -0.006648757576942443 -0.0015136339838504789" rpy="0 0 0"></origin>
		</visual>
		<collision>
			<geometry>
				<sphere radius="0.089842"></sphere>
			</geometry>
			<origin xyz="-2.6528875827789308e-06 -0.006648757576942443 -0.0015136339838504789" rpy="0 0 0"></origin>
		</collision>
		<inertial>
			<mass value="3.7"></mass>
			<origin rpy="0 0 0" xyz="0 0 0"></origin>
			<inertia ixx="0.010267495893" ixy="0.0" ixz="0.0" iyy="0.010267495893" iyz="0.0" izz="0.00666"></inertia>
		</inertial>
	</link>
	<link name="upper_arm_link_1">
		<visual>
			<geometry>
				<sphere radius="0.094923"></sphere>
			</geometry>
			<origin xyz="-0.29880514530599117 -2.2440966010107567e-05 0.13065568706798558" rpy="0 0 0"></origin>
		</visual>
		<visual>
			<geometry>
				<sphere radius="0.091263"></sphere>
			</geometry>
			<origin xyz="-0.4223871453059912 -2.9440966010107568e-05 0.12900468706798557" rpy="0 0 0"></origin>
		</visual>
		<visual>
			<geometry>
				<sphere radius="0.090758"></sphere>
			</geometry>
			<origin xyz="-0.00871114530599118 5.559033989892433e-06 0.13537768706798559" rpy="0 0 0"></origin>
		</visual>
		<visual>
			<geometry>
				<sphere radius="0.093838"></sphere>
			</geometry>
			<origin xyz="-0.3703041453059912 -2.5440966010107566e-05 0.13160568706798556" rpy="0 0 0"></origin>
		</visual>
		<visual>
			<geometry>
				<sphere radius="0.092897"></sphere>
			</geometry>
			<origin xyz="-0.08795214530599117 -3.440966010107567e-06 0.13541968706798557" rpy="0 0 0"></origin>
		</visual>
		<visual>
			<geometry>
				<sphere radius="0.093117"></sphere>
			</geometry>
			<origin xyz="-0.22120814530599117 -1.6440966010107567e-05 0.13292768706798558" rpy="0 0 0"></origin>
		</visual>
		<visual>
			<geometry>
				<sphere radius="0.089958"></sphere>
			</geometry>
			<origin xyz="-0.15866314530599118 -1.2440966010107567e-05 0.1317986870679856" rpy="0 0 0"></origin>
		</visual>
		<collision>
			<geometry>
				<sphere radius="0.094923"></sphere>
			</geometry>
			<origin xyz="-0.29880514530599117 -2.2440966010107567e-05 0.13065568706798558" rpy="0 0 0"></origin>
		</collision>
		<collision>
			<geometry>
				<sphere radius="0.091263"></sphere>
			</geometry>
			<origin xyz="-0.4223871453059912 -2.9440966010107568e-05 0.12900468706798557" rpy="0 0 0"></origin>
		</collision>
		<collision>
			<geometry>
				<sphere radius="0.090758"></sphere>
			</geometry>
			<origin xyz="-0.00871114530599118 5.559033989892433e-06 0.13537768706798559" rpy="0 0 0"></origin>
		</collision>
		<collision>
			<geometry>
				<sphere radius="0.093838"></sphere>
			</geometry>
			<origin xyz="-0.3703041453059912 -2.5440966010107566e-05 0.13160568706798556" rpy="0 0 0"></origin>
		</collision>
		<collision>
			<geometry>
				<sphere radius="0.092897"></sphere>
			</geometry>
			<origin xyz="-0.08795214530599117 -3.440966010107567e-06 0.13541968706798557" rpy="0 0 0"></origin>
		</collision>
		<collision>
			<geometry>
				<sphere radius="0.093117"></sphere>
			</geometry>
			<origin xyz="-0.22120814530599117 -1.6440966010107567e-05 0.13292768706798558" rpy="0 0 0"></origin>
		</collision>
		<collision>
			<geometry>
				<sphere radius="0.089958"></sphere>
			</geometry>
			<origin xyz="-0.15866314530599118 -1.2440966010107567e-05 0.1317986870679856" rpy="0 0 0"></origin>
		</collision>
		<inertial>
			<mass value="8.393"></mass>
			<origin rpy="0 1.5707963267948966 0" xyz="-0.2125 0.0 0.138"></origin>
			<inertia ixx="0.1338857818623325" ixy="0.0" ixz="0.0" iyy="0.1338857818623325" iyz="0.0" izz="0.0151074"></inertia>
		</inertial>
	</link>
	<link name="forearm_link_1">
		<visual>
			<geometry>
				<sphere radius="0.069786"></sphere>
			</geometry>
			<origin xyz="-0.3753460292737264 -0.0003035468224589817 -0.011400678107356396" rpy="0 0 0"></origin>
		</visual>
		<visual>
			<geometry>
				<sphere radius="0.073418"></sphere>
			</geometry>
			<origin xyz="-0.3729900292737264 0.0007594531775410182 0.022953321892643604" rpy="0 0 0"></origin>
		</visual>
		<visual>
			<geometry>
				<sphere radius="0.081417"></sphere>
			</geometry>
			<origin xyz="-0.2952910292737264 -0.00041054682245898175 0.009998321892643606" rpy="0 0 0"></origin>
		</visual>
		<visual>
			<geometry>
				<sphere radius="0.085647"></sphere>
			</geometry>
			<origin xyz="-0.21425702927372642 0.0004334531775410182 0.014403321892643605" rpy="0 0 0"></origin>
		</visual>
		<visual>
			<geometry>
				<sphere radius="0.087811"></sphere>
			</geometry>
			<origin xyz="-0.12363302927372641 0.00024745317754101825 0.012469321892643605" rpy="0 0 0"></origin>
		</visual>
		<visual>
			<geometry>
				<sphere radius="0.086674"></sphere>
			</geometry>
			<origin xyz="-0.045100029273726416 0.001873453177541018 0.014119321892643606" rpy="0 0 0"></origin>
		</visual>
		<visual>
			<geometry>
				<sphere radius="0.066154"></sphere>
			</geometry>
			<origin xyz="0.008519970726273585 0.010306453177541018 0.027016321892643604" rpy="0 0 0"></origin>
		</visual>
		<visual>
			<geometry>
				<sphere radius="0.070424"></sphere>
			</geometry>
			<origin xyz="0.007853970726273585 -0.011542546822458982 0.026729321892643605" rpy="0 0 0"></origin>
		</visual>
		<collision>
			<geometry>
				<sphere radius="0.069786"></sphere>
			</geometry>
			<origin xyz="-0.3753460292737264 -0.0003035468224589817 -0.011400678107356396" rpy="0 0 0"></origin>
		</collision>
		<collision>
			<geometry>
				<sphere radius="0.073418"></sphere>
			</geometry>
			<origin xyz="-0.3729900292737264 0.0007594531775410182 0.022953321892643604" rpy="0 0 0"></origin>
		</collision>
		<collision>
			<geometry>
				<sphere radius="0.081417"></sphere>
			</geometry>
			<origin xyz="-0.2952910292737264 -0.00041054682245898175 0.009998321892643606" rpy="0 0 0"></origin>
		</collision>
		<collision>
			<geometry>
				<sphere radius="0.085647"></sphere>
			</geometry>
			<origin xyz="-0.21425702927372642 0.0004334531775410182 0.014403321892643605" rpy="0 0 0"></origin>
		</collision>
		<collision>
			<geometry>
				<sphere radius="0.087811"></sphere>
			</geometry>
			<origin xyz="-0.12363302927372641 0.00024745317754101825 0.012469321892643605" rpy="0 0 0"></origin>
		</collision>
		<collision>
			<geometry>
				<sphere radius="0.086674"></sphere>
			</geometry>
			<origin xyz="-0.045100029273726416 0.001873453177541018 0.014119321892643606" rpy="0 0 0"></origin>
		</collision>
		<collision>
			<geometry>
				<sphere radius="0.066154"></sphere>
			</geometry>
			<origin xyz="0.008519970726273585 0.010306453177541018 0.027016321892643604" rpy="0 0 0"></origin>
		</collision>
		<collision>
			<geometry>
				<sphere radius="0.070424"></sphere>
			</geometry>
			<origin xyz="0.007853970726273585 -0.011542546822458982 0.026729321892643605" rpy="0 0 0"></origin>
		</collision>
		<inertial>
			<mass value="2.275"></mass>
			<origin rpy="0 1.5707963267948966 0" xyz="-0.1961 0.0 0.007"></origin>
			<inertia ixx="0.031209355099586295" ixy="0.0" ixz="0.0" iyy="0.031209355099586295" iyz="0.0" izz="0.004095"></inertia>
		</inertial>
	</link>
	<link name="wrist_1_link_1">
		<visual>
			<geometry>
				<sphere radius="0.076148"></sphere>
			</geometry>
			<origin xyz="-0.0002693220568518325 -0.002284190456157314 -0.013745301319436354" rpy="0 0 0"></origin>
		</visual>
		<collision>
			<geometry>
				<sphere radius="0.076148"></sphere>
			</geometry>
			<origin xyz="-0.0002693220568518325 -0.002284190456157314 -0.013745301319436354" rpy="0 0 0"></origin>
		</collision>
		<inertial>
			<mass value="1.219"></mass>
			<origin rpy="0 0 0" xyz="0 0 0"></origin>
			<inertia ixx="0.0025598989760400002" ixy="0.0" ixz="0.0" iyy="0.0025598989760400002" iyz="0.0" izz="0.0021942"></inertia>
		</inertial>
	</link>
	<link name="wrist_2_link_1">
		<visual>
			<geometry>
				<sphere radius="0.069339"></sphere>
			</geometry>
			<origin xyz="-0.0002282909261638736 0.00045500762583113464 -0.0012575461515493972" rpy="0 0 0"></origin>
		</visual>
		<collision>
			<geometry>
				<sphere radius="0.069339"></sphere>
			</geometry>
			<origin xyz="-0.0002282909261638736 0.00045500762583113464 -0.0012575461515493972" rpy="0 0 0"></origin>
		</collision>
		<inertial>
			<mass value="1.219"></mass>
			<origin rpy="0 0 0" xyz="0 0 0"></origin>
			<inertia ixx="0.0025598989760400002" ixy="0.0" ixz="0.0" iyy="0.0025598989760400002" iyz="0.0" izz="0.0021942"></inertia>
		</inertial>
	</link>
	<link name="wrist_3_link_1">
		<visual>
			<geometry>
				<sphere radius="0.044717"></sphere>
			</geometry>
			<origin xyz="-0.0002292038618326187 -0.00017992121219634642 -0.022866617411613468" rpy="0 0 0"></origin>
		</visual>
		<collision>
			<geometry>
				<sphere radius="0.044717"></sphere>
			</geometry>
			<origin xyz="-0.0002292038618326187 -0.00017992121219634642 -0.022866617411613468" rpy="0 0 0"></origin>
		</collision>
		<inertial>
			<mass value="0.1879"></mass>
			<origin rpy="0 0 0" xyz="0.0 0.0 -0.0229"></origin>
			<inertia ixx="9.890410052167731e-05" ixy="0.0" ixz="0.0" iyy="9.890410052167731e-05" iyz="0.0" izz="0.0001321171875"></inertia>
		</inertial>
	</link>
	<link name="flange_1"></link>
	<link name="tool1"></link>
	<link name="robotiq_arg2f_base_link">
		<inertial>
			<origin rpy="0 0 0" xyz="8.625E-08 -4.6583E-06 0.03145"></origin>
			<mass value="0.22652"></mass>
			<inertia ixx="0.00020005" ixy="-4.2442E-10" ixz="-2.9069E-10" iyy="0.00017832" iyz="-3.4402E-08" izz="0.00013478"></inertia>
		</inertial>
		<visual>
			<geometry>
				<sphere radius="0.053503"></sphere>
			</geometry>
			<origin xyz="-1e-06 -1e-06 0.03976211301029474" rpy="0 0 0"></origin>
		</visual>
		<collision>
			<geometry>
				<sphere radius="0.053503"></sphere>
			</geometry>
			<origin xyz="-1e-06 -1e-06 0.03976211301029474" rpy="0 0 0"></origin>
		</collision>
	</link>
	<link name="left_outer_knuckle">
		<inertial>
			<origin xyz="-0.000200000000003065 0.0199435877845359 0.0292245259211331" rpy="0 0 0"></origin>
			<mass value="0.00853198276973456"></mass>
			<inertia ixx="2.89328108496468E-06" ixy="-1.57935047237397E-19" ixz="-1.93980378593255E-19" iyy="1.86719750325683E-06" iyz="-1.21858577871576E-06" izz="1.21905238907251E-06"></inertia>
		</inertial>
		<visual>
			<geometry>
				<sphere radius="0.011261"></sphere>
			</geometry>
			<origin xyz="0.0 0.0022970895633697506 0.00036984966278076105" rpy="0 0 0"></origin>
		</visual>
		<visual>
			<geometry>
				<sphere radius="0.013955"></sphere>
			</geometry>
			<origin xyz="0.0 0.01660808956336975 0.001498849662780761" rpy="0 0 0"></origin>
		</visual>
		<visual>
			<geometry>
				<sphere radius="0.014264"></sphere>
			</geometry>
			<origin xyz="0.0 0.02677008956336975 0.0017918496627807611" rpy="0 0 0"></origin>
		</visual>
		<collision>
			<geometry>
				<sphere radius="0.011261"></sphere>
			</geometry>
			<origin xyz="0.0 0.0022970895633697506 0.00036984966278076105" rpy="0 0 0"></origin>
		</collision>
		<collision>
			<geometry>
				<sphere radius="0.013955"></sphere>
			</geometry>
			<origin xyz="0.0 0.01660808956336975 0.001498849662780761" rpy="0 0 0"></origin>
		</collision>
		<collision>
			<geometry>
				<sphere radius="0.014264"></sphere>
			</geometry>
			<origin xyz="0.0 0.02677008956336975 0.0017918496627807611" rpy="0 0 0"></origin>
		</collision>
	</link>
	<link name="left_outer_finger">
		<inertial>
			<origin xyz="0.00030115855001899 0.0373907951953854 -0.0208027427000385" rpy="0 0 0"></origin>
			<mass value="0.022614240507152"></mass>
			<inertia ixx="1.52518312458174E-05" ixy="9.76583423954399E-10" ixz="-5.43838577022588E-10" iyy="6.17694243867776E-06" iyz="6.78636130740228E-06" izz="1.16494917907219E-05"></inertia>
		</inertial>
		<visual>
			<geometry>
				<sphere radius="0.013081"></sphere>
			</geometry>
			<origin xyz="-0.005135 0.005531375192642213 0.0426294749660492" rpy="0 0 0"></origin>
		</visual>
		<visual>
			<geometry>
				<sphere radius="0.014548"></sphere>
			</geometry>
			<origin xyz="0.007378 0.0051113751926422125 0.0393954749660492" rpy="0 0 0"></origin>
		</visual>
		<visual>
			<geometry>
				<sphere radius="0.01525"></sphere>
			</geometry>
			<origin xyz="-0.006824 0.0025623751926422125 0.019744474966049197" rpy="0 0 0"></origin>
		</visual>
		<visual>
			<geometry>
				<sphere radius="0.014756"></sphere>
			</geometry>
			<origin xyz="0.007378 0.0017983751926422124 0.013852474966049196" rpy="0 0 0"></origin>
		</visual>
		<visual>
			<geometry>
				<sphere radius="0.014265"></sphere>
			</geometry>
			<origin xyz="-0.000242 0.00017837519264221223 0.0013104749660491945" rpy="0 0 0"></origin>
		</visual>
		<collision>
			<geometry>
				<sphere radius="0.013081"></sphere>
			</geometry>
			<origin xyz="-0.005135 0.005531375192642213 0.0426294749660492" rpy="0 0 0"></origin>
		</collision>
		<collision>
			<geometry>
				<sphere radius="0.014548"></sphere>
			</geometry>
			<origin xyz="0.007378 0.0051113751926422125 0.0393954749660492" rpy="0 0 0"></origin>
		</collision>
		<collision>
			<geometry>
				<sphere radius="0.01525"></sphere>
			</geometry>
			<origin xyz="-0.006824 0.0025623751926422125 0.019744474966049197" rpy="0 0 0"></origin>
		</collision>
		<collision>
			<geometry>
				<sphere radius="0.014756"></sphere>
			</geometry>
			<origin xyz="0.007378 0.0017983751926422124 0.013852474966049196" rpy="0 0 0"></origin>
		</collision>
		<collision>
			<geometry>
				<sphere radius="0.014265"></sphere>
			</geometry>
			<origin xyz="-0.000242 0.00017837519264221223 0.0013104749660491945" rpy="0 0 0"></origin>
		</collision>
	</link>
	<link name="left_inner_finger">
		<inertial>
			<origin xyz="0.000299999999999317 0.0160078233491243 -0.0136945669206257" rpy="0 0 0"></origin>
			<mass value="0.0104003125914103"></mass>
			<inertia ixx="2.71909453810972E-06" ixy="1.35402465472579E-21" ixz="-7.1817349065269E-22" iyy="7.69100314106116E-07" iyz="6.74715432769696E-07" izz="2.30315190420171E-06"></inertia>
		</inertial>
		<visual>
			<geometry>
				<sphere radius="0.01218"></sphere>
			</geometry>
			<origin xyz="9.42949999999964e-06 -0.003017347 0.0013782770000000041" rpy="0 0 0"></origin>
		</visual>
		<visual>
			<geometry>
				<sphere radius="0.01124"></sphere>
			</geometry>
			<origin xyz="8.429499999999639e-06 -0.012436347 0.006195277000000001" rpy="0 0 0"></origin>
		</visual>
		<visual>
			<geometry>
				<sphere radius="0.010284"></sphere>
			</geometry>
			<origin xyz="0.0004904294999999996 -0.015311347 0.016237277" rpy="0 0 0"></origin>
		</visual>
		<visual>
			<geometry>
				<sphere radius="0.011778"></sphere>
			</geometry>
			<origin xyz="8.429499999999639e-06 -0.016391347 0.008709277000000001" rpy="0 0 0"></origin>
		</visual>
		<visual>
			<geometry>
				<sphere radius="0.009281"></sphere>
			</geometry>
			<origin xyz="-0.00015257050000000037 -0.015361347000000001 0.027253277" rpy="0 0 0"></origin>
		</visual>
		<visual>
			<geometry>
				<sphere radius="0.008271"></sphere>
			</geometry>
			<origin xyz="0.0036064294999999997 -0.015462347 0.038306277" rpy="0 0 0"></origin>
		</visual>
		<visual>
			<geometry>
				<sphere radius="0.008221"></sphere>
			</geometry>
			<origin xyz="-0.0036105705 -0.015462347 0.038357277" rpy="0 0 0"></origin>
		</visual>
		<collision>
			<geometry>
				<sphere radius="0.01218"></sphere>
			</geometry>
			<origin xyz="9.42949999999964e-06 -0.003017347 0.0013782770000000041" rpy="0 0 0"></origin>
		</collision>
		<collision>
			<geometry>
				<sphere radius="0.01124"></sphere>
			</geometry>
			<origin xyz="8.429499999999639e-06 -0.012436347 0.006195277000000001" rpy="0 0 0"></origin>
		</collision>
		<collision>
			<geometry>
				<sphere radius="0.010284"></sphere>
			</geometry>
			<origin xyz="0.0004904294999999996 -0.015311347 0.016237277" rpy="0 0 0"></origin>
		</collision>
		<collision>
			<geometry>
				<sphere radius="0.011778"></sphere>
			</geometry>
			<origin xyz="8.429499999999639e-06 -0.016391347 0.008709277000000001" rpy="0 0 0"></origin>
		</collision>
		<collision>
			<geometry>
				<sphere radius="0.009281"></sphere>
			</geometry>
			<origin xyz="-0.00015257050000000037 -0.015361347000000001 0.027253277" rpy="0 0 0"></origin>
		</collision>
		<collision>
			<geometry>
				<sphere radius="0.008271"></sphere>
			</geometry>
			<origin xyz="0.0036064294999999997 -0.015462347 0.038306277" rpy="0 0 0"></origin>
		</collision>
		<collision>
			<geometry>
				<sphere radius="0.008221"></sphere>
			</geometry>
			<origin xyz="-0.0036105705 -0.015462347 0.038357277" rpy="0 0 0"></origin>
		</collision>
	</link>
	<link name="left_inner_finger_pad">
		<inertial>
			<origin rpy="0 0 0" xyz="0 0 0"></origin>
			<mass value="0.11"></mass>
			<inertia ixx="1.0E-05" ixy="0" ixz="0" iyy="1.0E-05" iyz="0" izz="1.0E-06"></inertia>
		</inertial>
		<visual>
			<geometry>
				<sphere radius="0.015281"></sphere>
			</geometry>
			<origin xyz="0.0 -1e-06 -0.0275" rpy="0 0 0"></origin>
		</visual>
		<visual>
			<geometry>
				<sphere radius="0.01477"></sphere>
			</geometry>
			<origin xyz="-9.7e-05 0.0 -0.015971" rpy="0 0 0"></origin>
		</visual>
		<visual>
			<geometry>
				<sphere radius="0.015009"></sphere>
			</geometry>
			<origin xyz="-2.9e-05 0.0 -0.001829" rpy="0 0 0"></origin>
		</visual>
		<visual>
			<geometry>
				<sphere radius="0.015176"></sphere>
			</geometry>
			<origin xyz="0.000124 0.0 0.012607" rpy="0 0 0"></origin>
		</visual>
		<visual>
			<geometry>
				<sphere radius="0.012342"></sphere>
			</geometry>
			<origin xyz="0.004069 -1e-06 0.028069" rpy="0 0 0"></origin>
		</visual>
		<visual>
			<geometry>
				<sphere radius="0.013923"></sphere>
			</geometry>
			<origin xyz="-0.003501 0.0 0.02598" rpy="0 0 0"></origin>
		</visual>
		<collision>
			<geometry>
				<sphere radius="0.015281"></sphere>
			</geometry>
			<origin xyz="0.0 -1e-06 -0.0275" rpy="0 0 0"></origin>
		</collision>
		<collision>
			<geometry>
				<sphere radius="0.01477"></sphere>
			</geometry>
			<origin xyz="-9.7e-05 0.0 -0.015971" rpy="0 0 0"></origin>
		</collision>
		<collision>
			<geometry>
				<sphere radius="0.015009"></sphere>
			</geometry>
			<origin xyz="-2.9e-05 0.0 -0.001829" rpy="0 0 0"></origin>
		</collision>
		<collision>
			<geometry>
				<sphere radius="0.015176"></sphere>
			</geometry>
			<origin xyz="0.000124 0.0 0.012607" rpy="0 0 0"></origin>
		</collision>
		<collision>
			<geometry>
				<sphere radius="0.012342"></sphere>
			</geometry>
			<origin xyz="0.004069 -1e-06 0.028069" rpy="0 0 0"></origin>
		</collision>
		<collision>
			<geometry>
				<sphere radius="0.013923"></sphere>
			</geometry>
			<origin xyz="-0.003501 0.0 0.02598" rpy="0 0 0"></origin>
		</collision>
	</link>
	<link name="left_inner_knuckle">
		<inertial>
			<origin xyz="0.000123011831763771 0.0507850843201817 0.00103968640075166" rpy="0 0 0"></origin>
			<mass value="0.0271177346495152"></mass>
			<inertia ixx="2.61910379223783E-05" ixy="-2.43616858946494E-07" ixz="-6.37789906117123E-09" iyy="2.8270243746167E-06" iyz="-5.37200748039765E-07" izz="2.83695868220296E-05"></inertia>
		</inertial>
		<visual>
			<geometry>
				<sphere radius="0.01486"></sphere>
			</geometry>
			<origin xyz="0.010146 0.003594960271835328 0.004208610754013062" rpy="0 0 0"></origin>
		</visual>
		<visual>
			<geometry>
				<sphere radius="0.014049"></sphere>
			</geometry>
			<origin xyz="-0.009674 0.0025979602718353284 0.0030416107540130605" rpy="0 0 0"></origin>
		</visual>
		<visual>
			<geometry>
				<sphere radius="0.015606"></sphere>
			</geometry>
			<origin xyz="-0.008911 0.015702960271835327 0.01838561075401306" rpy="0 0 0"></origin>
		</visual>
		<visual>
			<geometry>
				<sphere radius="0.015752"></sphere>
			</geometry>
			<origin xyz="0.011381 0.018904960271835327 0.022137610754013062" rpy="0 0 0"></origin>
		</visual>
		<visual>
			<geometry>
				<sphere radius="0.015341"></sphere>
			</geometry>
			<origin xyz="-0.009018 0.03143796027183533 0.03681061075401306" rpy="0 0 0"></origin>
		</visual>
		<visual>
			<geometry>
				<sphere radius="0.01437"></sphere>
			</geometry>
			<origin xyz="0.005911 0.03429096027183533 0.040150610754013064" rpy="0 0 0"></origin>
		</visual>
		<collision>
			<geometry>
				<sphere radius="0.01486"></sphere>
			</geometry>
			<origin xyz="0.010146 0.003594960271835328 0.004208610754013062" rpy="0 0 0"></origin>
		</collision>
		<collision>
			<geometry>
				<sphere radius="0.014049"></sphere>
			</geometry>
			<origin xyz="-0.009674 0.0025979602718353284 0.0030416107540130605" rpy="0 0 0"></origin>
		</collision>
		<collision>
			<geometry>
				<sphere radius="0.015606"></sphere>
			</geometry>
			<origin xyz="-0.008911 0.015702960271835327 0.01838561075401306" rpy="0 0 0"></origin>
		</collision>
		<collision>
			<geometry>
				<sphere radius="0.015752"></sphere>
			</geometry>
			<origin xyz="0.011381 0.018904960271835327 0.022137610754013062" rpy="0 0 0"></origin>
		</collision>
		<collision>
			<geometry>
				<sphere radius="0.015341"></sphere>
			</geometry>
			<origin xyz="-0.009018 0.03143796027183533 0.03681061075401306" rpy="0 0 0"></origin>
		</collision>
		<collision>
			<geometry>
				<sphere radius="0.01437"></sphere>
			</geometry>
			<origin xyz="0.005911 0.03429096027183533 0.040150610754013064" rpy="0 0 0"></origin>
		</collision>
	</link>
	<link name="right_outer_knuckle">
		<inertial>
			<origin xyz="-0.000200000000003065 0.0199435877845359 0.0292245259211331" rpy="0 0 0"></origin>
			<mass value="0.00853198276973456"></mass>
			<inertia ixx="2.89328108496468E-06" ixy="-1.57935047237397E-19" ixz="-1.93980378593255E-19" iyy="1.86719750325683E-06" iyz="-1.21858577871576E-06" izz="1.21905238907251E-06"></inertia>
		</inertial>
		<visual>
			<geometry>
				<sphere radius="0.011261"></sphere>
			</geometry>
			<origin xyz="0.0 0.0022970895633697506 0.00036984966278076105" rpy="0 0 0"></origin>
		</visual>
		<visual>
			<geometry>
				<sphere radius="0.013955"></sphere>
			</geometry>
			<origin xyz="0.0 0.01660808956336975 0.001498849662780761" rpy="0 0 0"></origin>
		</visual>
		<visual>
			<geometry>
				<sphere radius="0.014264"></sphere>
			</geometry>
			<origin xyz="0.0 0.02677008956336975 0.0017918496627807611" rpy="0 0 0"></origin>
		</visual>
		<collision>
			<geometry>
				<sphere radius="0.011261"></sphere>
			</geometry>
			<origin xyz="0.0 0.0022970895633697506 0.00036984966278076105" rpy="0 0 0"></origin>
		</collision>
		<collision>
			<geometry>
				<sphere radius="0.013955"></sphere>
			</geometry>
			<origin xyz="0.0 0.01660808956336975 0.001498849662780761" rpy="0 0 0"></origin>
		</collision>
		<collision>
			<geometry>
				<sphere radius="0.014264"></sphere>
			</geometry>
			<origin xyz="0.0 0.02677008956336975 0.0017918496627807611" rpy="0 0 0"></origin>
		</collision>
	</link>
	<link name="right_outer_finger">
		<inertial>
			<origin xyz="0.00030115855001899 0.0373907951953854 -0.0208027427000385" rpy="0 0 0"></origin>
			<mass value="0.022614240507152"></mass>
			<inertia ixx="1.52518312458174E-05" ixy="9.76583423954399E-10" ixz="-5.43838577022588E-10" iyy="6.17694243867776E-06" iyz="6.78636130740228E-06" izz="1.16494917907219E-05"></inertia>
		</inertial>
		<visual>
			<geometry>
				<sphere radius="0.013081"></sphere>
			</geometry>
			<origin xyz="-0.005135 0.005531375192642213 0.0426294749660492" rpy="0 0 0"></origin>
		</visual>
		<visual>
			<geometry>
				<sphere radius="0.014548"></sphere>
			</geometry>
			<origin xyz="0.007378 0.0051113751926422125 0.0393954749660492" rpy="0 0 0"></origin>
		</visual>
		<visual>
			<geometry>
				<sphere radius="0.01525"></sphere>
			</geometry>
			<origin xyz="-0.006824 0.0025623751926422125 0.019744474966049197" rpy="0 0 0"></origin>
		</visual>
		<visual>
			<geometry>
				<sphere radius="0.014756"></sphere>
			</geometry>
			<origin xyz="0.007378 0.0017983751926422124 0.013852474966049196" rpy="0 0 0"></origin>
		</visual>
		<visual>
			<geometry>
				<sphere radius="0.014265"></sphere>
			</geometry>
			<origin xyz="-0.000242 0.00017837519264221223 0.0013104749660491945" rpy="0 0 0"></origin>
		</visual>
		<collision>
			<geometry>
				<sphere radius="0.013081"></sphere>
			</geometry>
			<origin xyz="-0.005135 0.005531375192642213 0.0426294749660492" rpy="0 0 0"></origin>
		</collision>
		<collision>
			<geometry>
				<sphere radius="0.014548"></sphere>
			</geometry>
			<origin xyz="0.007378 0.0051113751926422125 0.0393954749660492" rpy="0 0 0"></origin>
		</collision>
		<collision>
			<geometry>
				<sphere radius="0.01525"></sphere>
			</geometry>
			<origin xyz="-0.006824 0.0025623751926422125 0.019744474966049197" rpy="0 0 0"></origin>
		</collision>
		<collision>
			<geometry>
				<sphere radius="0.014756"></sphere>
			</geometry>
			<origin xyz="0.007378 0.0017983751926422124 0.013852474966049196" rpy="0 0 0"></origin>
		</collision>
		<collision>
			<geometry>
				<sphere radius="0.014265"></sphere>
			</geometry>
			<origin xyz="-0.000242 0.00017837519264221223 0.0013104749660491945" rpy="0 0 0"></origin>
		</collision>
	</link>
	<link name="right_inner_finger">
		<inertial>
			<origin xyz="0.000299999999999317 0.0160078233491243 -0.0136945669206257" rpy="0 0 0"></origin>
			<mass value="0.0104003125914103"></mass>
			<inertia ixx="2.71909453810972E-06" ixy="1.35402465472579E-21" ixz="-7.1817349065269E-22" iyy="7.69100314106116E-07" iyz="6.74715432769696E-07" izz="2.30315190420171E-06"></inertia>
		</inertial>
		<visual>
			<geometry>
				<sphere radius="0.01218"></sphere>
			</geometry>
			<origin xyz="9.42949999999964e-06 -0.003017347 0.0013782770000000041" rpy="0 0 0"></origin>
		</visual>
		<visual>
			<geometry>
				<sphere radius="0.01124"></sphere>
			</geometry>
			<origin xyz="8.429499999999639e-06 -0.012436347 0.006195277000000001" rpy="0 0 0"></origin>
		</visual>
		<visual>
			<geometry>
				<sphere radius="0.010284"></sphere>
			</geometry>
			<origin xyz="0.0004904294999999996 -0.015311347 0.016237277" rpy="0 0 0"></origin>
		</visual>
		<visual>
			<geometry>
				<sphere radius="0.011778"></sphere>
			</geometry>
			<origin xyz="8.429499999999639e-06 -0.016391347 0.008709277000000001" rpy="0 0 0"></origin>
		</visual>
		<visual>
			<geometry>
				<sphere radius="0.009281"></sphere>
			</geometry>
			<origin xyz="-0.00015257050000000037 -0.015361347000000001 0.027253277" rpy="0 0 0"></origin>
		</visual>
		<visual>
			<geometry>
				<sphere radius="0.008271"></sphere>
			</geometry>
			<origin xyz="0.0036064294999999997 -0.015462347 0.038306277" rpy="0 0 0"></origin>
		</visual>
		<visual>
			<geometry>
				<sphere radius="0.008221"></sphere>
			</geometry>
			<origin xyz="-0.0036105705 -0.015462347 0.038357277" rpy="0 0 0"></origin>
		</visual>
		<collision>
			<geometry>
				<sphere radius="0.01218"></sphere>
			</geometry>
			<origin xyz="9.42949999999964e-06 -0.003017347 0.0013782770000000041" rpy="0 0 0"></origin>
		</collision>
		<collision>
			<geometry>
				<sphere radius="0.01124"></sphere>
			</geometry>
			<origin xyz="8.429499999999639e-06 -0.012436347 0.006195277000000001" rpy="0 0 0"></origin>
		</collision>
		<collision>
			<geometry>
				<sphere radius="0.010284"></sphere>
			</geometry>
			<origin xyz="0.0004904294999999996 -0.015311347 0.016237277" rpy="0 0 0"></origin>
		</collision>
		<collision>
			<geometry>
				<sphere radius="0.011778"></sphere>
			</geometry>
			<origin xyz="8.429499999999639e-06 -0.016391347 0.008709277000000001" rpy="0 0 0"></origin>
		</collision>
		<collision>
			<geometry>
				<sphere radius="0.009281"></sphere>
			</geometry>
			<origin xyz="-0.00015257050000000037 -0.015361347000000001 0.027253277" rpy="0 0 0"></origin>
		</collision>
		<collision>
			<geometry>
				<sphere radius="0.008271"></sphere>
			</geometry>
			<origin xyz="0.0036064294999999997 -0.015462347 0.038306277" rpy="0 0 0"></origin>
		</collision>
		<collision>
			<geometry>
				<sphere radius="0.008221"></sphere>
			</geometry>
			<origin xyz="-0.0036105705 -0.015462347 0.038357277" rpy="0 0 0"></origin>
		</collision>
	</link>
	<link name="right_inner_finger_pad">
		<inertial>
			<origin rpy="0 0 0" xyz="0 0 0"></origin>
			<mass value="0.11"></mass>
			<inertia ixx="0.000010" ixy="0" ixz="0" iyy="0.000010" iyz="0" izz="0.000001"></inertia>
		</inertial>
		<visual>
			<geometry>
				<sphere radius="0.015281"></sphere>
			</geometry>
			<origin xyz="0.0 -1e-06 -0.0275" rpy="0 0 0"></origin>
		</visual>
		<visual>
			<geometry>
				<sphere radius="0.01477"></sphere>
			</geometry>
			<origin xyz="-9.7e-05 0.0 -0.015971" rpy="0 0 0"></origin>
		</visual>
		<visual>
			<geometry>
				<sphere radius="0.015009"></sphere>
			</geometry>
			<origin xyz="-2.9e-05 0.0 -0.001829" rpy="0 0 0"></origin>
		</visual>
		<visual>
			<geometry>
				<sphere radius="0.015176"></sphere>
			</geometry>
			<origin xyz="0.000124 0.0 0.012607" rpy="0 0 0"></origin>
		</visual>
		<visual>
			<geometry>
				<sphere radius="0.012342"></sphere>
			</geometry>
			<origin xyz="0.004069 -1e-06 0.028069" rpy="0 0 0"></origin>
		</visual>
		<visual>
			<geometry>
				<sphere radius="0.013923"></sphere>
			</geometry>
			<origin xyz="-0.003501 0.0 0.02598" rpy="0 0 0"></origin>
		</visual>
		<collision>
			<geometry>
				<sphere radius="0.015281"></sphere>
			</geometry>
			<origin xyz="0.0 -1e-06 -0.0275" rpy="0 0 0"></origin>
		</collision>
		<collision>
			<geometry>
				<sphere radius="0.01477"></sphere>
			</geometry>
			<origin xyz="-9.7e-05 0.0 -0.015971" rpy="0 0 0"></origin>
		</collision>
		<collision>
			<geometry>
				<sphere radius="0.015009"></sphere>
			</geometry>
			<origin xyz="-2.9e-05 0.0 -0.001829" rpy="0 0 0"></origin>
		</collision>
		<collision>
			<geometry>
				<sphere radius="0.015176"></sphere>
			</geometry>
			<origin xyz="0.000124 0.0 0.012607" rpy="0 0 0"></origin>
		</collision>
		<collision>
			<geometry>
				<sphere radius="0.012342"></sphere>
			</geometry>
			<origin xyz="0.004069 -1e-06 0.028069" rpy="0 0 0"></origin>
		</collision>
		<collision>
			<geometry>
				<sphere radius="0.013923"></sphere>
			</geometry>
			<origin xyz="-0.003501 0.0 0.02598" rpy="0 0 0"></origin>
		</collision>
	</link>
	<link name="right_inner_knuckle">
		<inertial>
			<origin xyz="0.000123011831763771 0.0507850843201817 0.00103968640075166" rpy="0 0 0"></origin>
			<mass value="0.0271177346495152"></mass>
			<inertia ixx="2.61910379223783E-05" ixy="-2.43616858946494E-07" ixz="-6.37789906117123E-09" iyy="2.8270243746167E-06" iyz="-5.37200748039765E-07" izz="2.83695868220296E-05"></inertia>
		</inertial>
		<visual>
			<geometry>
				<sphere radius="0.01486"></sphere>
			</geometry>
			<origin xyz="0.010146 0.003594960271835328 0.004208610754013062" rpy="0 0 0"></origin>
		</visual>
		<visual>
			<geometry>
				<sphere radius="0.014049"></sphere>
			</geometry>
			<origin xyz="-0.009674 0.0025979602718353284 0.0030416107540130605" rpy="0 0 0"></origin>
		</visual>
		<visual>
			<geometry>
				<sphere radius="0.015606"></sphere>
			</geometry>
			<origin xyz="-0.008911 0.015702960271835327 0.01838561075401306" rpy="0 0 0"></origin>
		</visual>
		<visual>
			<geometry>
				<sphere radius="0.015752"></sphere>
			</geometry>
			<origin xyz="0.011381 0.018904960271835327 0.022137610754013062" rpy="0 0 0"></origin>
		</visual>
		<visual>
			<geometry>
				<sphere radius="0.015341"></sphere>
			</geometry>
			<origin xyz="-0.009018 0.03143796027183533 0.03681061075401306" rpy="0 0 0"></origin>
		</visual>
		<visual>
			<geometry>
				<sphere radius="0.01437"></sphere>
			</geometry>
			<origin xyz="0.005911 0.03429096027183533 0.040150610754013064" rpy="0 0 0"></origin>
		</visual>
		<collision>
			<geometry>
				<sphere radius="0.01486"></sphere>
			</geometry>
			<origin xyz="0.010146 0.003594960271835328 0.004208610754013062" rpy="0 0 0"></origin>
		</collision>
		<collision>
			<geometry>
				<sphere radius="0.014049"></sphere>
			</geometry>
			<origin xyz="-0.009674 0.0025979602718353284 0.0030416107540130605" rpy="0 0 0"></origin>
		</collision>
		<collision>
			<geometry>
				<sphere radius="0.015606"></sphere>
			</geometry>
			<origin xyz="-0.008911 0.015702960271835327 0.01838561075401306" rpy="0 0 0"></origin>
		</collision>
		<collision>
			<geometry>
				<sphere radius="0.015752"></sphere>
			</geometry>
			<origin xyz="0.011381 0.018904960271835327 0.022137610754013062" rpy="0 0 0"></origin>
		</collision>
		<collision>
			<geometry>
				<sphere radius="0.015341"></sphere>
			</geometry>
			<origin xyz="-0.009018 0.03143796027183533 0.03681061075401306" rpy="0 0 0"></origin>
		</collision>
		<collision>
			<geometry>
				<sphere radius="0.01437"></sphere>
			</geometry>
			<origin xyz="0.005911 0.03429096027183533 0.040150610754013064" rpy="0 0 0"></origin>
		</collision>
	</link>
	<link name="dummy_center_indicator_link"></link>
	<link name="robotiq_arg2f_base_link_1">
		<inertial>
			<origin rpy="0 0 0" xyz="8.625E-08 -4.6583E-06 0.03145"></origin>
			<mass value="0.22652"></mass>
			<inertia ixx="0.00020005" ixy="-4.2442E-10" ixz="-2.9069E-10" iyy="0.00017832" iyz="-3.4402E-08" izz="0.00013478"></inertia>
		</inertial>
		<visual>
			<geometry>
				<sphere radius="0.053503"></sphere>
			</geometry>
			<origin xyz="-1e-06 -1e-06 0.03976211301029474" rpy="0 0 0"></origin>
		</visual>
		<collision>
			<geometry>
				<sphere radius="0.053503"></sphere>
			</geometry>
			<origin xyz="-1e-06 -1e-06 0.03976211301029474" rpy="0 0 0"></origin>
		</collision>
	</link>
	<link name="left_outer_knuckle_1">
		<inertial>
			<origin xyz="-0.000200000000003065 0.0199435877845359 0.0292245259211331" rpy="0 0 0"></origin>
			<mass value="0.00853198276973456"></mass>
			<inertia ixx="2.89328108496468E-06" ixy="-1.57935047237397E-19" ixz="-1.93980378593255E-19" iyy="1.86719750325683E-06" iyz="-1.21858577871576E-06" izz="1.21905238907251E-06"></inertia>
		</inertial>
		<visual>
			<geometry>
				<sphere radius="0.011261"></sphere>
			</geometry>
			<origin xyz="0.0 0.0022970895633697506 0.00036984966278076105" rpy="0 0 0"></origin>
		</visual>
		<visual>
			<geometry>
				<sphere radius="0.013955"></sphere>
			</geometry>
			<origin xyz="0.0 0.01660808956336975 0.001498849662780761" rpy="0 0 0"></origin>
		</visual>
		<visual>
			<geometry>
				<sphere radius="0.014264"></sphere>
			</geometry>
			<origin xyz="0.0 0.02677008956336975 0.0017918496627807611" rpy="0 0 0"></origin>
		</visual>
		<collision>
			<geometry>
				<sphere radius="0.011261"></sphere>
			</geometry>
			<origin xyz="0.0 0.0022970895633697506 0.00036984966278076105" rpy="0 0 0"></origin>
		</collision>
		<collision>
			<geometry>
				<sphere radius="0.013955"></sphere>
			</geometry>
			<origin xyz="0.0 0.01660808956336975 0.001498849662780761" rpy="0 0 0"></origin>
		</collision>
		<collision>
			<geometry>
				<sphere radius="0.014264"></sphere>
			</geometry>
			<origin xyz="0.0 0.02677008956336975 0.0017918496627807611" rpy="0 0 0"></origin>
		</collision>
	</link>
	<link name="left_outer_finger_1">
		<inertial>
			<origin xyz="0.00030115855001899 0.0373907951953854 -0.0208027427000385" rpy="0 0 0"></origin>
			<mass value="0.022614240507152"></mass>
			<inertia ixx="1.52518312458174E-05" ixy="9.76583423954399E-10" ixz="-5.43838577022588E-10" iyy="6.17694243867776E-06" iyz="6.78636130740228E-06" izz="1.16494917907219E-05"></inertia>
		</inertial>
		<visual>
			<geometry>
				<sphere radius="0.013081"></sphere>
			</geometry>
			<origin xyz="-0.005135 0.005531375192642213 0.0426294749660492" rpy="0 0 0"></origin>
		</visual>
		<visual>
			<geometry>
				<sphere radius="0.014548"></sphere>
			</geometry>
			<origin xyz="0.007378 0.0051113751926422125 0.0393954749660492" rpy="0 0 0"></origin>
		</visual>
		<visual>
			<geometry>
				<sphere radius="0.01525"></sphere>
			</geometry>
			<origin xyz="-0.006824 0.0025623751926422125 0.019744474966049197" rpy="0 0 0"></origin>
		</visual>
		<visual>
			<geometry>
				<sphere radius="0.014756"></sphere>
			</geometry>
			<origin xyz="0.007378 0.0017983751926422124 0.013852474966049196" rpy="0 0 0"></origin>
		</visual>
		<visual>
			<geometry>
				<sphere radius="0.014265"></sphere>
			</geometry>
			<origin xyz="-0.000242 0.00017837519264221223 0.0013104749660491945" rpy="0 0 0"></origin>
		</visual>
		<collision>
			<geometry>
				<sphere radius="0.013081"></sphere>
			</geometry>
			<origin xyz="-0.005135 0.005531375192642213 0.0426294749660492" rpy="0 0 0"></origin>
		</collision>
		<collision>
			<geometry>
				<sphere radius="0.014548"></sphere>
			</geometry>
			<origin xyz="0.007378 0.0051113751926422125 0.0393954749660492" rpy="0 0 0"></origin>
		</collision>
		<collision>
			<geometry>
				<sphere radius="0.01525"></sphere>
			</geometry>
			<origin xyz="-0.006824 0.0025623751926422125 0.019744474966049197" rpy="0 0 0"></origin>
		</collision>
		<collision>
			<geometry>
				<sphere radius="0.014756"></sphere>
			</geometry>
			<origin xyz="0.007378 0.0017983751926422124 0.013852474966049196" rpy="0 0 0"></origin>
		</collision>
		<collision>
			<geometry>
				<sphere radius="0.014265"></sphere>
			</geometry>
			<origin xyz="-0.000242 0.00017837519264221223 0.0013104749660491945" rpy="0 0 0"></origin>
		</collision>
	</link>
	<link name="left_inner_finger_1">
		<inertial>
			<origin xyz="0.000299999999999317 0.0160078233491243 -0.0136945669206257" rpy="0 0 0"></origin>
			<mass value="0.0104003125914103"></mass>
			<inertia ixx="2.71909453810972E-06" ixy="1.35402465472579E-21" ixz="-7.1817349065269E-22" iyy="7.69100314106116E-07" iyz="6.74715432769696E-07" izz="2.30315190420171E-06"></inertia>
		</inertial>
		<visual>
			<geometry>
				<sphere radius="0.01218"></sphere>
			</geometry>
			<origin xyz="9.42949999999964e-06 -0.003017347 0.0013782770000000041" rpy="0 0 0"></origin>
		</visual>
		<visual>
			<geometry>
				<sphere radius="0.01124"></sphere>
			</geometry>
			<origin xyz="8.429499999999639e-06 -0.012436347 0.006195277000000001" rpy="0 0 0"></origin>
		</visual>
		<visual>
			<geometry>
				<sphere radius="0.010284"></sphere>
			</geometry>
			<origin xyz="0.0004904294999999996 -0.015311347 0.016237277" rpy="0 0 0"></origin>
		</visual>
		<visual>
			<geometry>
				<sphere radius="0.011778"></sphere>
			</geometry>
			<origin xyz="8.429499999999639e-06 -0.016391347 0.008709277000000001" rpy="0 0 0"></origin>
		</visual>
		<visual>
			<geometry>
				<sphere radius="0.009281"></sphere>
			</geometry>
			<origin xyz="-0.00015257050000000037 -0.015361347000000001 0.027253277" rpy="0 0 0"></origin>
		</visual>
		<visual>
			<geometry>
				<sphere radius="0.008271"></sphere>
			</geometry>
			<origin xyz="0.0036064294999999997 -0.015462347 0.038306277" rpy="0 0 0"></origin>
		</visual>
		<visual>
			<geometry>
				<sphere radius="0.008221"></sphere>
			</geometry>
			<origin xyz="-0.0036105705 -0.015462347 0.038357277" rpy="0 0 0"></origin>
		</visual>
		<collision>
			<geometry>
				<sphere radius="0.01218"></sphere>
			</geometry>
			<origin xyz="9.42949999999964e-06 -0.003017347 0.0013782770000000041" rpy="0 0 0"></origin>
		</collision>
		<collision>
			<geometry>
				<sphere radius="0.01124"></sphere>
			</geometry>
			<origin xyz="8.429499999999639e-06 -0.012436347 0.006195277000000001" rpy="0 0 0"></origin>
		</collision>
		<collision>
			<geometry>
				<sphere radius="0.010284"></sphere>
			</geometry>
			<origin xyz="0.0004904294999999996 -0.015311347 0.016237277" rpy="0 0 0"></origin>
		</collision>
		<collision>
			<geometry>
				<sphere radius="0.011778"></sphere>
			</geometry>
			<origin xyz="8.429499999999639e-06 -0.016391347 0.008709277000000001" rpy="0 0 0"></origin>
		</collision>
		<collision>
			<geometry>
				<sphere radius="0.009281"></sphere>
			</geometry>
			<origin xyz="-0.00015257050000000037 -0.015361347000000001 0.027253277" rpy="0 0 0"></origin>
		</collision>
		<collision>
			<geometry>
				<sphere radius="0.008271"></sphere>
			</geometry>
			<origin xyz="0.0036064294999999997 -0.015462347 0.038306277" rpy="0 0 0"></origin>
		</collision>
		<collision>
			<geometry>
				<sphere radius="0.008221"></sphere>
			</geometry>
			<origin xyz="-0.0036105705 -0.015462347 0.038357277" rpy="0 0 0"></origin>
		</collision>
	</link>
	<link name="left_inner_finger_pad_1">
		<inertial>
			<origin rpy="0 0 0" xyz="0 0 0"></origin>
			<mass value="0.11"></mass>
			<inertia ixx="1.0E-05" ixy="0" ixz="0" iyy="1.0E-05" iyz="0" izz="1.0E-06"></inertia>
		</inertial>
		<visual>
			<geometry>
				<sphere radius="0.015281"></sphere>
			</geometry>
			<origin xyz="0.0 -1e-06 -0.0275" rpy="0 0 0"></origin>
		</visual>
		<visual>
			<geometry>
				<sphere radius="0.01477"></sphere>
			</geometry>
			<origin xyz="-9.7e-05 0.0 -0.015971" rpy="0 0 0"></origin>
		</visual>
		<visual>
			<geometry>
				<sphere radius="0.015009"></sphere>
			</geometry>
			<origin xyz="-2.9e-05 0.0 -0.001829" rpy="0 0 0"></origin>
		</visual>
		<visual>
			<geometry>
				<sphere radius="0.015176"></sphere>
			</geometry>
			<origin xyz="0.000124 0.0 0.012607" rpy="0 0 0"></origin>
		</visual>
		<visual>
			<geometry>
				<sphere radius="0.012342"></sphere>
			</geometry>
			<origin xyz="0.004069 -1e-06 0.028069" rpy="0 0 0"></origin>
		</visual>
		<visual>
			<geometry>
				<sphere radius="0.013923"></sphere>
			</geometry>
			<origin xyz="-0.003501 0.0 0.02598" rpy="0 0 0"></origin>
		</visual>
		<collision>
			<geometry>
				<sphere radius="0.015281"></sphere>
			</geometry>
			<origin xyz="0.0 -1e-06 -0.0275" rpy="0 0 0"></origin>
		</collision>
		<collision>
			<geometry>
				<sphere radius="0.01477"></sphere>
			</geometry>
			<origin xyz="-9.7e-05 0.0 -0.015971" rpy="0 0 0"></origin>
		</collision>
		<collision>
			<geometry>
				<sphere radius="0.015009"></sphere>
			</geometry>
			<origin xyz="-2.9e-05 0.0 -0.001829" rpy="0 0 0"></origin>
		</collision>
		<collision>
			<geometry>
				<sphere radius="0.015176"></sphere>
			</geometry>
			<origin xyz="0.000124 0.0 0.012607" rpy="0 0 0"></origin>
		</collision>
		<collision>
			<geometry>
				<sphere radius="0.012342"></sphere>
			</geometry>
			<origin xyz="0.004069 -1e-06 0.028069" rpy="0 0 0"></origin>
		</collision>
		<collision>
			<geometry>
				<sphere radius="0.013923"></sphere>
			</geometry>
			<origin xyz="-0.003501 0.0 0.02598" rpy="0 0 0"></origin>
		</collision>
	</link>
	<link name="left_inner_knuckle_1">
		<inertial>
			<origin xyz="0.000123011831763771 0.0507850843201817 0.00103968640075166" rpy="0 0 0"></origin>
			<mass value="0.0271177346495152"></mass>
			<inertia ixx="2.61910379223783E-05" ixy="-2.43616858946494E-07" ixz="-6.37789906117123E-09" iyy="2.8270243746167E-06" iyz="-5.37200748039765E-07" izz="2.83695868220296E-05"></inertia>
		</inertial>
		<visual>
			<geometry>
				<sphere radius="0.01486"></sphere>
			</geometry>
			<origin xyz="0.010146 0.003594960271835328 0.004208610754013062" rpy="0 0 0"></origin>
		</visual>
		<visual>
			<geometry>
				<sphere radius="0.014049"></sphere>
			</geometry>
			<origin xyz="-0.009674 0.0025979602718353284 0.0030416107540130605" rpy="0 0 0"></origin>
		</visual>
		<visual>
			<geometry>
				<sphere radius="0.015606"></sphere>
			</geometry>
			<origin xyz="-0.008911 0.015702960271835327 0.01838561075401306" rpy="0 0 0"></origin>
		</visual>
		<visual>
			<geometry>
				<sphere radius="0.015752"></sphere>
			</geometry>
			<origin xyz="0.011381 0.018904960271835327 0.022137610754013062" rpy="0 0 0"></origin>
		</visual>
		<visual>
			<geometry>
				<sphere radius="0.015341"></sphere>
			</geometry>
			<origin xyz="-0.009018 0.03143796027183533 0.03681061075401306" rpy="0 0 0"></origin>
		</visual>
		<visual>
			<geometry>
				<sphere radius="0.01437"></sphere>
			</geometry>
			<origin xyz="0.005911 0.03429096027183533 0.040150610754013064" rpy="0 0 0"></origin>
		</visual>
		<collision>
			<geometry>
				<sphere radius="0.01486"></sphere>
			</geometry>
			<origin xyz="0.010146 0.003594960271835328 0.004208610754013062" rpy="0 0 0"></origin>
		</collision>
		<collision>
			<geometry>
				<sphere radius="0.014049"></sphere>
			</geometry>
			<origin xyz="-0.009674 0.0025979602718353284 0.0030416107540130605" rpy="0 0 0"></origin>
		</collision>
		<collision>
			<geometry>
				<sphere radius="0.015606"></sphere>
			</geometry>
			<origin xyz="-0.008911 0.015702960271835327 0.01838561075401306" rpy="0 0 0"></origin>
		</collision>
		<collision>
			<geometry>
				<sphere radius="0.015752"></sphere>
			</geometry>
			<origin xyz="0.011381 0.018904960271835327 0.022137610754013062" rpy="0 0 0"></origin>
		</collision>
		<collision>
			<geometry>
				<sphere radius="0.015341"></sphere>
			</geometry>
			<origin xyz="-0.009018 0.03143796027183533 0.03681061075401306" rpy="0 0 0"></origin>
		</collision>
		<collision>
			<geometry>
				<sphere radius="0.01437"></sphere>
			</geometry>
			<origin xyz="0.005911 0.03429096027183533 0.040150610754013064" rpy="0 0 0"></origin>
		</collision>
	</link>
	<link name="right_outer_knuckle_1">
		<inertial>
			<origin xyz="-0.000200000000003065 0.0199435877845359 0.0292245259211331" rpy="0 0 0"></origin>
			<mass value="0.00853198276973456"></mass>
			<inertia ixx="2.89328108496468E-06" ixy="-1.57935047237397E-19" ixz="-1.93980378593255E-19" iyy="1.86719750325683E-06" iyz="-1.21858577871576E-06" izz="1.21905238907251E-06"></inertia>
		</inertial>
		<visual>
			<geometry>
				<sphere radius="0.011261"></sphere>
			</geometry>
			<origin xyz="0.0 0.0022970895633697506 0.00036984966278076105" rpy="0 0 0"></origin>
		</visual>
		<visual>
			<geometry>
				<sphere radius="0.013955"></sphere>
			</geometry>
			<origin xyz="0.0 0.01660808956336975 0.001498849662780761" rpy="0 0 0"></origin>
		</visual>
		<visual>
			<geometry>
				<sphere radius="0.014264"></sphere>
			</geometry>
			<origin xyz="0.0 0.02677008956336975 0.0017918496627807611" rpy="0 0 0"></origin>
		</visual>
		<collision>
			<geometry>
				<sphere radius="0.011261"></sphere>
			</geometry>
			<origin xyz="0.0 0.0022970895633697506 0.00036984966278076105" rpy="0 0 0"></origin>
		</collision>
		<collision>
			<geometry>
				<sphere radius="0.013955"></sphere>
			</geometry>
			<origin xyz="0.0 0.01660808956336975 0.001498849662780761" rpy="0 0 0"></origin>
		</collision>
		<collision>
			<geometry>
				<sphere radius="0.014264"></sphere>
			</geometry>
			<origin xyz="0.0 0.02677008956336975 0.0017918496627807611" rpy="0 0 0"></origin>
		</collision>
	</link>
	<link name="right_outer_finger_1">
		<inertial>
			<origin xyz="0.00030115855001899 0.0373907951953854 -0.0208027427000385" rpy="0 0 0"></origin>
			<mass value="0.022614240507152"></mass>
			<inertia ixx="1.52518312458174E-05" ixy="9.76583423954399E-10" ixz="-5.43838577022588E-10" iyy="6.17694243867776E-06" iyz="6.78636130740228E-06" izz="1.16494917907219E-05"></inertia>
		</inertial>
		<visual>
			<geometry>
				<sphere radius="0.013081"></sphere>
			</geometry>
			<origin xyz="-0.005135 0.005531375192642213 0.0426294749660492" rpy="0 0 0"></origin>
		</visual>
		<visual>
			<geometry>
				<sphere radius="0.014548"></sphere>
			</geometry>
			<origin xyz="0.007378 0.0051113751926422125 0.0393954749660492" rpy="0 0 0"></origin>
		</visual>
		<visual>
			<geometry>
				<sphere radius="0.01525"></sphere>
			</geometry>
			<origin xyz="-0.006824 0.0025623751926422125 0.019744474966049197" rpy="0 0 0"></origin>
		</visual>
		<visual>
			<geometry>
				<sphere radius="0.014756"></sphere>
			</geometry>
			<origin xyz="0.007378 0.0017983751926422124 0.013852474966049196" rpy="0 0 0"></origin>
		</visual>
		<visual>
			<geometry>
				<sphere radius="0.014265"></sphere>
			</geometry>
			<origin xyz="-0.000242 0.00017837519264221223 0.0013104749660491945" rpy="0 0 0"></origin>
		</visual>
		<collision>
			<geometry>
				<sphere radius="0.013081"></sphere>
			</geometry>
			<origin xyz="-0.005135 0.005531375192642213 0.0426294749660492" rpy="0 0 0"></origin>
		</collision>
		<collision>
			<geometry>
				<sphere radius="0.014548"></sphere>
			</geometry>
			<origin xyz="0.007378 0.0051113751926422125 0.0393954749660492" rpy="0 0 0"></origin>
		</collision>
		<collision>
			<geometry>
				<sphere radius="0.01525"></sphere>
			</geometry>
			<origin xyz="-0.006824 0.0025623751926422125 0.019744474966049197" rpy="0 0 0"></origin>
		</collision>
		<collision>
			<geometry>
				<sphere radius="0.014756"></sphere>
			</geometry>
			<origin xyz="0.007378 0.0017983751926422124 0.013852474966049196" rpy="0 0 0"></origin>
		</collision>
		<collision>
			<geometry>
				<sphere radius="0.014265"></sphere>
			</geometry>
			<origin xyz="-0.000242 0.00017837519264221223 0.0013104749660491945" rpy="0 0 0"></origin>
		</collision>
	</link>
	<link name="right_inner_finger_1">
		<inertial>
			<origin xyz="0.000299999999999317 0.0160078233491243 -0.0136945669206257" rpy="0 0 0"></origin>
			<mass value="0.0104003125914103"></mass>
			<inertia ixx="2.71909453810972E-06" ixy="1.35402465472579E-21" ixz="-7.1817349065269E-22" iyy="7.69100314106116E-07" iyz="6.74715432769696E-07" izz="2.30315190420171E-06"></inertia>
		</inertial>
		<visual>
			<geometry>
				<sphere radius="0.01218"></sphere>
			</geometry>
			<origin xyz="9.42949999999964e-06 -0.003017347 0.0013782770000000041" rpy="0 0 0"></origin>
		</visual>
		<visual>
			<geometry>
				<sphere radius="0.01124"></sphere>
			</geometry>
			<origin xyz="8.429499999999639e-06 -0.012436347 0.006195277000000001" rpy="0 0 0"></origin>
		</visual>
		<visual>
			<geometry>
				<sphere radius="0.010284"></sphere>
			</geometry>
			<origin xyz="0.0004904294999999996 -0.015311347 0.016237277" rpy="0 0 0"></origin>
		</visual>
		<visual>
			<geometry>
				<sphere radius="0.011778"></sphere>
			</geometry>
			<origin xyz="8.429499999999639e-06 -0.016391347 0.008709277000000001" rpy="0 0 0"></origin>
		</visual>
		<visual>
			<geometry>
				<sphere radius="0.009281"></sphere>
			</geometry>
			<origin xyz="-0.00015257050000000037 -0.015361347000000001 0.027253277" rpy="0 0 0"></origin>
		</visual>
		<visual>
			<geometry>
				<sphere radius="0.008271"></sphere>
			</geometry>
			<origin xyz="0.0036064294999999997 -0.015462347 0.038306277" rpy="0 0 0"></origin>
		</visual>
		<visual>
			<geometry>
				<sphere radius="0.008221"></sphere>
			</geometry>
			<origin xyz="-0.0036105705 -0.015462347 0.038357277" rpy="0 0 0"></origin>
		</visual>
		<collision>
			<geometry>
				<sphere radius="0.01218"></sphere>
			</geometry>
			<origin xyz="9.42949999999964e-06 -0.003017347 0.0013782770000000041" rpy="0 0 0"></origin>
		</collision>
		<collision>
			<geometry>
				<sphere radius="0.01124"></sphere>
			</geometry>
			<origin xyz="8.429499999999639e-06 -0.012436347 0.006195277000000001" rpy="0 0 0"></origin>
		</collision>
		<collision>
			<geometry>
				<sphere radius="0.010284"></sphere>
			</geometry>
			<origin xyz="0.0004904294999999996 -0.015311347 0.016237277" rpy="0 0 0"></origin>
		</collision>
		<collision>
			<geometry>
				<sphere radius="0.011778"></sphere>
			</geometry>
			<origin xyz="8.429499999999639e-06 -0.016391347 0.008709277000000001" rpy="0 0 0"></origin>
		</collision>
		<collision>
			<geometry>
				<sphere radius="0.009281"></sphere>
			</geometry>
			<origin xyz="-0.00015257050000000037 -0.015361347000000001 0.027253277" rpy="0 0 0"></origin>
		</collision>
		<collision>
			<geometry>
				<sphere radius="0.008271"></sphere>
			</geometry>
			<origin xyz="0.0036064294999999997 -0.015462347 0.038306277" rpy="0 0 0"></origin>
		</collision>
		<collision>
			<geometry>
				<sphere radius="0.008221"></sphere>
			</geometry>
			<origin xyz="-0.0036105705 -0.015462347 0.038357277" rpy="0 0 0"></origin>
		</collision>
	</link>
	<link name="right_inner_finger_pad_1">
		<inertial>
			<origin rpy="0 0 0" xyz="0 0 0"></origin>
			<mass value="0.11"></mass>
			<inertia ixx="0.000010" ixy="0" ixz="0" iyy="0.000010" iyz="0" izz="0.000001"></inertia>
		</inertial>
		<visual>
			<geometry>
				<sphere radius="0.015281"></sphere>
			</geometry>
			<origin xyz="0.0 -1e-06 -0.0275" rpy="0 0 0"></origin>
		</visual>
		<visual>
			<geometry>
				<sphere radius="0.01477"></sphere>
			</geometry>
			<origin xyz="-9.7e-05 0.0 -0.015971" rpy="0 0 0"></origin>
		</visual>
		<visual>
			<geometry>
				<sphere radius="0.015009"></sphere>
			</geometry>
			<origin xyz="-2.9e-05 0.0 -0.001829" rpy="0 0 0"></origin>
		</visual>
		<visual>
			<geometry>
				<sphere radius="0.015176"></sphere>
			</geometry>
			<origin xyz="0.000124 0.0 0.012607" rpy="0 0 0"></origin>
		</visual>
		<visual>
			<geometry>
				<sphere radius="0.012342"></sphere>
			</geometry>
			<origin xyz="0.004069 -1e-06 0.028069" rpy="0 0 0"></origin>
		</visual>
		<visual>
			<geometry>
				<sphere radius="0.013923"></sphere>
			</geometry>
			<origin xyz="-0.003501 0.0 0.02598" rpy="0 0 0"></origin>
		</visual>
		<collision>
			<geometry>
				<sphere radius="0.015281"></sphere>
			</geometry>
			<origin xyz="0.0 -1e-06 -0.0275" rpy="0 0 0"></origin>
		</collision>
		<collision>
			<geometry>
				<sphere radius="0.01477"></sphere>
			</geometry>
			<origin xyz="-9.7e-05 0.0 -0.015971" rpy="0 0 0"></origin>
		</collision>
		<collision>
			<geometry>
				<sphere radius="0.015009"></sphere>
			</geometry>
			<origin xyz="-2.9e-05 0.0 -0.001829" rpy="0 0 0"></origin>
		</collision>
		<collision>
			<geometry>
				<sphere radius="0.015176"></sphere>
			</geometry>
			<origin xyz="0.000124 0.0 0.012607" rpy="0 0 0"></origin>
		</collision>
		<collision>
			<geometry>
				<sphere radius="0.012342"></sphere>
			</geometry>
			<origin xyz="0.004069 -1e-06 0.028069" rpy="0 0 0"></origin>
		</collision>
		<collision>
			<geometry>
				<sphere radius="0.013923"></sphere>
			</geometry>
			<origin xyz="-0.003501 0.0 0.02598" rpy="0 0 0"></origin>
		</collision>
	</link>
	<link name="right_inner_knuckle_1">
		<inertial>
			<origin xyz="0.000123011831763771 0.0507850843201817 0.00103968640075166" rpy="0 0 0"></origin>
			<mass value="0.0271177346495152"></mass>
			<inertia ixx="2.61910379223783E-05" ixy="-2.43616858946494E-07" ixz="-6.37789906117123E-09" iyy="2.8270243746167E-06" iyz="-5.37200748039765E-07" izz="2.83695868220296E-05"></inertia>
		</inertial>
		<visual>
			<geometry>
				<sphere radius="0.01486"></sphere>
			</geometry>
			<origin xyz="0.010146 0.003594960271835328 0.004208610754013062" rpy="0 0 0"></origin>
		</visual>
		<visual>
			<geometry>
				<sphere radius="0.014049"></sphere>
			</geometry>
			<origin xyz="-0.009674 0.0025979602718353284 0.0030416107540130605" rpy="0 0 0"></origin>
		</visual>
		<visual>
			<geometry>
				<sphere radius="0.015606"></sphere>
			</geometry>
			<origin xyz="-0.008911 0.015702960271835327 0.01838561075401306" rpy="0 0 0"></origin>
		</visual>
		<visual>
			<geometry>
				<sphere radius="0.015752"></sphere>
			</geometry>
			<origin xyz="0.011381 0.018904960271835327 0.022137610754013062" rpy="0 0 0"></origin>
		</visual>
		<visual>
			<geometry>
				<sphere radius="0.015341"></sphere>
			</geometry>
			<origin xyz="-0.009018 0.03143796027183533 0.03681061075401306" rpy="0 0 0"></origin>
		</visual>
		<visual>
			<geometry>
				<sphere radius="0.01437"></sphere>
			</geometry>
			<origin xyz="0.005911 0.03429096027183533 0.040150610754013064" rpy="0 0 0"></origin>
		</visual>
		<collision>
			<geometry>
				<sphere radius="0.01486"></sphere>
			</geometry>
			<origin xyz="0.010146 0.003594960271835328 0.004208610754013062" rpy="0 0 0"></origin>
		</collision>
		<collision>
			<geometry>
				<sphere radius="0.014049"></sphere>
			</geometry>
			<origin xyz="-0.009674 0.0025979602718353284 0.0030416107540130605" rpy="0 0 0"></origin>
		</collision>
		<collision>
			<geometry>
				<sphere radius="0.015606"></sphere>
			</geometry>
			<origin xyz="-0.008911 0.015702960271835327 0.01838561075401306" rpy="0 0 0"></origin>
		</collision>
		<collision>
			<geometry>
				<sphere radius="0.015752"></sphere>
			</geometry>
			<origin xyz="0.011381 0.018904960271835327 0.022137610754013062" rpy="0 0 0"></origin>
		</collision>
		<collision>
			<geometry>
				<sphere radius="0.015341"></sphere>
			</geometry>
			<origin xyz="-0.009018 0.03143796027183533 0.03681061075401306" rpy="0 0 0"></origin>
		</collision>
		<collision>
			<geometry>
				<sphere radius="0.01437"></sphere>
			</geometry>
			<origin xyz="0.005911 0.03429096027183533 0.040150610754013064" rpy="0 0 0"></origin>
		</collision>
	</link>
	<link name="dummy_center_indicator_link_1"></link>
	<joint name="base_fixture_j_base_link" type="fixed">
		<parent link="base_fixture_link"></parent>
		<child link="base_link"></child>
		<origin rpy=" 0 0 0" xyz="-0.55 0.0 0.0"></origin>
	</joint>
	<joint name="base_fixture_j_base_link_1" type="fixed">
		<parent link="base_fixture_link"></parent>
		<child link="base_link_1"></child>
		<origin rpy=" 0 0 0" xyz="0.55 0.0 0.0"></origin>
	</joint>
	<joint name="base_link-base_link_inertia" type="fixed">
		<parent link="base_link"></parent>
		<child link="base_link_inertia"></child>
		<origin rpy="0 0 3.141592653589793" xyz="0 0 0"></origin>
	</joint>
	<joint name="shoulder_pan_joint" type="revolute">
		<parent link="base_link_inertia"></parent>
		<child link="shoulder_link"></child>
		<origin rpy="0 0 0" xyz="0 0 0.1625"></origin>
		<axis xyz="0 0 1"></axis>
		<limit effort="150.0" lower="-1.57" upper="1.57" velocity="3.141592653589793"></limit>
		<dynamics damping="0" friction="0"></dynamics>
	</joint>
	<joint name="shoulder_lift_joint" type="revolute">
		<parent link="shoulder_link"></parent>
		<child link="upper_arm_link"></child>
		<origin rpy="1.570796327 0 0" xyz="0 0 0"></origin>
		<axis xyz="0 0 1"></axis>
		<limit effort="150.0" lower="-3.141592653589793" upper="3.141592653589793" velocity="3.141592653589793"></limit>
		<dynamics damping="0" friction="0"></dynamics>
	</joint>
	<joint name="elbow_joint" type="revolute">
		<parent link="upper_arm_link"></parent>
		<child link="forearm_link"></child>
		<origin rpy="0 0 0" xyz="-0.425 0 0"></origin>
		<axis xyz="0 0 1"></axis>
		<limit effort="150.0" lower="0" upper="3.141592653589793" velocity="3.141592653589793"></limit>
		<dynamics damping="0" friction="0"></dynamics>
	</joint>
	<joint name="wrist_1_joint" type="revolute">
		<parent link="forearm_link"></parent>
		<child link="wrist_1_link"></child>
		<origin rpy="0 0 0" xyz="-0.3922 0 0.1333"></origin>
		<axis xyz="0 0 1"></axis>
		<limit effort="150.0" lower="-3.141592653589793" upper="0" velocity="3.141592653589793"></limit>
		<dynamics damping="0" friction="0"></dynamics>
	</joint>
	<joint name="wrist_2_joint" type="revolute">
		<parent link="wrist_1_link"></parent>
		<child link="wrist_2_link"></child>
		<origin rpy="1.570796327 0 0" xyz="0 -0.0997 -2.044881182297852e-11"></origin>
		<axis xyz="0 0 1"></axis>
		<limit effort="150.0" lower="-3.141592653589793" upper="3.141592653589793" velocity="3.141592653589793"></limit>
		<dynamics damping="0" friction="0"></dynamics>
	</joint>
	<joint name="wrist_3_joint" type="revolute">
		<parent link="wrist_2_link"></parent>
		<child link="wrist_3_link"></child>
		<origin rpy="1.570796326589793 3.141592653589793 3.141592653589793" xyz="0 0.0996 -2.042830148012698e-11"></origin>
		<axis xyz="0 0 1"></axis>
		<limit effort="150.0" lower="-3.141592653589793" upper="3.141592653589793" velocity="3.141592653589793"></limit>
		<dynamics damping="0" friction="0"></dynamics>
	</joint>
	<joint name="base_link-base_fixed_joint" type="fixed">
		<origin rpy="0 0 0" xyz="0 0 0"></origin>
		<parent link="base_link"></parent>
		<child link="base"></child>
	</joint>
	<joint name="wrist_3-flange" type="fixed">
		<parent link="wrist_3_link"></parent>
		<child link="flange"></child>
		<origin rpy="0 -1.57079632679 -1.57079632679" xyz="0 0 0"></origin>
	</joint>
	<joint name="flange-tool0" type="fixed">
		<origin rpy="1.57079632679 0 1.57079632679" xyz="0 0 0"></origin>
		<parent link="flange"></parent>
		<child link="tool0"></child>
	</joint>
	<joint name="base_link-base_link_inertia_1" type="fixed">
		<parent link="base_link_1"></parent>
		<child link="base_link_inertia_1"></child>
		<origin rpy="0 0 0" xyz="0 0 0"></origin>
	</joint>
	<joint name="shoulder_pan_joint_1" type="revolute">
		<parent link="base_link_inertia_1"></parent>
		<child link="shoulder_link_1"></child>
		<origin rpy="0 0 0" xyz="0 0 0.1625"></origin>
		<axis xyz="0 0 1"></axis>
		<limit effort="150.0" lower="-1.57" upper="1.57" velocity="3.141592653589793"></limit>
		<dynamics damping="0" friction="0"></dynamics>
	</joint>
	<joint name="shoulder_lift_joint_1" type="revolute">
		<parent link="shoulder_link_1"></parent>
		<child link="upper_arm_link_1"></child>
		<origin rpy="1.570796327 0 0" xyz="0 0 0"></origin>
		<axis xyz="0 0 1"></axis>
		<limit effort="150.0" lower="-3.141592653589793" upper="3.141592653589793" velocity="3.141592653589793"></limit>
		<dynamics damping="0" friction="0"></dynamics>
	</joint>
	<joint name="elbow_joint_1" type="revolute">
		<parent link="upper_arm_link_1"></parent>
		<child link="forearm_link_1"></child>
		<origin rpy="0 0 0" xyz="-0.425 0 0"></origin>
		<axis xyz="0 0 1"></axis>
		<limit effort="150.0" lower="0" upper="3.141592653589793" velocity="3.141592653589793"></limit>
		<dynamics damping="0" friction="0"></dynamics>
	</joint>
	<joint name="wrist_1_joint_1" type="revolute">
		<parent link="forearm_link_1"></parent>
		<child link="wrist_1_link_1"></child>
		<origin rpy="0 0 0" xyz="-0.3922 0 0.1333"></origin>
		<axis xyz="0 0 1"></axis>
		<limit effort="150.0" lower="-3.141592653589793" upper="0" velocity="3.141592653589793"></limit>
		<dynamics damping="0" friction="0"></dynamics>
	</joint>
	<joint name="wrist_2_joint_1" type="revolute">
		<parent link="wrist_1_link_1"></parent>
		<child link="wrist_2_link_1"></child>
		<origin rpy="1.570796327 0 0" xyz="0 -0.0997 -2.044881182297852e-11"></origin>
		<axis xyz="0 0 1"></axis>
		<limit effort="150.0" lower="-3.141592653589793" upper="3.141592653589793" velocity="3.141592653589793"></limit>
		<dynamics damping="0" friction="0"></dynamics>
	</joint>
	<joint name="wrist_3_joint_1" type="revolute">
		<parent link="wrist_2_link_1"></parent>
		<child link="wrist_3_link_1"></child>
		<origin rpy="1.570796326589793 3.141592653589793 3.141592653589793" xyz="0 0.0996 -2.042830148012698e-11"></origin>
		<axis xyz="0 0 1"></axis>
		<limit effort="150.0" lower="-3.141592653589793" upper="3.141592653589793" velocity="3.141592653589793"></limit>
		<dynamics damping="0" friction="0"></dynamics>
	</joint>
	<joint name="wrist_3-flange_1" type="fixed">
		<parent link="wrist_3_link_1"></parent>
		<child link="flange_1"></child>
		<origin rpy="0 -1.57079632679 -1.57079632679" xyz="0 0 0"></origin>
	</joint>
	<joint name="flange-tool1" type="fixed">
		<origin rpy="1.57079632679 0 1.57079632679" xyz="0 0 0"></origin>
		<parent link="flange_1"></parent>
		<child link="tool1"></child>
	</joint>
	<joint name="flange-gripper" type="fixed">
		<origin rpy="1.57079632679 0 1.57079632679" xyz="0 0 0"></origin>
		<parent link="flange"></parent>
		<child link="robotiq_arg2f_base_link"></child>
	</joint>
	<joint name="finger_joint" type="revolute">
		<origin rpy="0 0 3.141592653589793" xyz="0 -0.0306011 0.054904"></origin>
		<parent link="robotiq_arg2f_base_link"></parent>
		<child link="left_outer_knuckle"></child>
		<axis xyz="1 0 0"></axis>
		<limit effort="1000" lower="0" upper="0.8" velocity="100.2"></limit>
	</joint>
	<joint name="left_outer_finger_joint" type="fixed">
		<origin rpy="0 0 0" xyz="0 0.0315 -0.0041"></origin>
		<parent link="left_outer_knuckle"></parent>
		<child link="left_outer_finger"></child>
		<axis xyz="1 0 0"></axis>
	</joint>
	<joint name="left_inner_knuckle_joint" type="revolute">
		<origin rpy="0 0 3.141592653589793" xyz="0 -0.0127 0.06142"></origin>
		<parent link="robotiq_arg2f_base_link"></parent>
		<child link="left_inner_knuckle"></child>
		<axis xyz="1 0 0"></axis>
		<limit effort="1000" lower="0" upper="0.8" velocity="100.2"></limit>
		<mimic joint="finger_joint" multiplier="1" offset="0"></mimic>
	</joint>
	<joint name="left_inner_finger_joint" type="revolute">
		<origin rpy="0 0 0" xyz="0 0.0061 0.0471"></origin>
		<parent link="left_outer_finger"></parent>
		<child link="left_inner_finger"></child>
		<axis xyz="1 0 0"></axis>
		<limit effort="1000" lower="-0.8" upper="0" velocity="100.2"></limit>
		<mimic joint="finger_joint" multiplier="-1" offset="0"></mimic>
	</joint>
	<joint name="left_inner_finger_pad_joint" type="fixed">
		<origin rpy="0 0 0" xyz="0 -0.0190203446692936 0.03867"></origin>
		<parent link="left_inner_finger"></parent>
		<child link="left_inner_finger_pad"></child>
		<axis xyz="0 0 1"></axis>
	</joint>
	<joint name="right_outer_knuckle_joint" type="revolute">
		<origin rpy="0 0 0" xyz="0 0.0306011 0.054904"></origin>
		<parent link="robotiq_arg2f_base_link"></parent>
		<child link="right_outer_knuckle"></child>
		<axis xyz="1 0 0"></axis>
		<limit effort="1000" lower="0" upper="0.8" velocity="100.2"></limit>
		<mimic joint="finger_joint" multiplier="1" offset="0"></mimic>
	</joint>
	<joint name="right_outer_finger_joint" type="fixed">
		<origin rpy="0 0 0" xyz="0 0.0315 -0.0041"></origin>
		<parent link="right_outer_knuckle"></parent>
		<child link="right_outer_finger"></child>
		<axis xyz="1 0 0"></axis>
	</joint>
	<joint name="right_inner_knuckle_joint" type="revolute">
		<origin rpy="0 0 0.0" xyz="0 0.0127 0.06142"></origin>
		<parent link="robotiq_arg2f_base_link"></parent>
		<child link="right_inner_knuckle"></child>
		<axis xyz="1 0 0"></axis>
		<limit effort="1000" lower="0" upper="0.8" velocity="100.2"></limit>
		<mimic joint="finger_joint" multiplier="1" offset="0"></mimic>
	</joint>
	<joint name="right_inner_finger_joint" type="revolute">
		<origin rpy="0 0 0" xyz="0 0.0061 0.0471"></origin>
		<parent link="right_outer_finger"></parent>
		<child link="right_inner_finger"></child>
		<axis xyz="1 0 0"></axis>
		<limit effort="1000" lower="-0.8" upper="0" velocity="100.2"></limit>
		<mimic joint="finger_joint" multiplier="-1" offset="0"></mimic>
	</joint>
	<joint name="right_inner_finger_pad_joint" type="fixed">
		<origin rpy="0 0 0" xyz="0 -0.0190203446692936 0.03867"></origin>
		<parent link="right_inner_finger"></parent>
		<child link="right_inner_finger_pad"></child>
		<axis xyz="0 0 1"></axis>
	</joint>
	<joint name="dummy_center_fixed_joint" type="fixed">
		<parent link="robotiq_arg2f_base_link"></parent>
		<child link="dummy_center_indicator_link"></child>
		<origin xyz="0 0 0.1725"></origin>
	</joint>
	<joint name="flange-gripper_1" type="fixed">
		<origin rpy="1.57079632679 0 1.57079632679" xyz="0 0 0"></origin>
		<parent link="flange_1"></parent>
		<child link="robotiq_arg2f_base_link_1"></child>
	</joint>
	<joint name="finger_joint_1" type="revolute">
		<origin rpy="0 0 3.141592653589793" xyz="0 -0.0306011 0.054904"></origin>
		<parent link="robotiq_arg2f_base_link_1"></parent>
		<child link="left_outer_knuckle_1"></child>
		<axis xyz="1 0 0"></axis>
		<limit effort="1000" lower="0" upper="0.8" velocity="100.2"></limit>
	</joint>
	<joint name="left_outer_finger_joint_1" type="fixed">
		<origin rpy="0 0 0" xyz="0 0.0315 -0.0041"></origin>
		<parent link="left_outer_knuckle_1"></parent>
		<child link="left_outer_finger_1"></child>
		<axis xyz="1 0 0"></axis>
	</joint>
	<joint name="left_inner_knuckle_joint_1" type="revolute">
		<origin rpy="0 0 3.141592653589793" xyz="0 -0.0127 0.06142"></origin>
		<parent link="robotiq_arg2f_base_link_1"></parent>
		<child link="left_inner_knuckle_1"></child>
		<axis xyz="1 0 0"></axis>
		<limit effort="1000" lower="0" upper="0.8" velocity="100.2"></limit>
		<mimic joint="finger_joint_1" multiplier="1" offset="0"></mimic>
	</joint>
	<joint name="left_inner_finger_joint_1" type="revolute">
		<origin rpy="0 0 0" xyz="0 0.0061 0.0471"></origin>
		<parent link="left_outer_finger_1"></parent>
		<child link="left_inner_finger_1"></child>
		<axis xyz="1 0 0"></axis>
		<limit effort="1000" lower="-0.8" upper="0" velocity="100.2"></limit>
		<mimic joint="finger_joint_1" multiplier="-1" offset="0"></mimic>
	</joint>
	<joint name="left_inner_finger_pad_joint_1" type="fixed">
		<origin rpy="0 0 0" xyz="0 -0.0190203446692936 0.03867"></origin>
		<parent link="left_inner_finger_1"></parent>
		<child link="left_inner_finger_pad_1"></child>
		<axis xyz="0 0 1"></axis>
	</joint>
	<joint name="right_outer_knuckle_joint_1" type="revolute">
		<origin rpy="0 0 0" xyz="0 0.0306011 0.054904"></origin>
		<parent link="robotiq_arg2f_base_link_1"></parent>
		<child link="right_outer_knuckle_1"></child>
		<axis xyz="1 0 0"></axis>
		<limit effort="1000" lower="0" upper="0.8" velocity="100.2"></limit>
		<mimic joint="finger_joint_1" multiplier="1" offset="0"></mimic>
	</joint>
	<joint name="right_outer_finger_joint_1" type="fixed">
		<origin rpy="0 0 0" xyz="0 0.0315 -0.0041"></origin>
		<parent link="right_outer_knuckle_1"></parent>
		<child link="right_outer_finger_1"></child>
		<axis xyz="1 0 0"></axis>
	</joint>
	<joint name="right_inner_knuckle_joint_1" type="revolute">
		<origin rpy="0 0 0.0" xyz="0 0.0127 0.06142"></origin>
		<parent link="robotiq_arg2f_base_link_1"></parent>
		<child link="right_inner_knuckle_1"></child>
		<axis xyz="1 0 0"></axis>
		<limit effort="1000" lower="0" upper="0.8" velocity="100.2"></limit>
		<mimic joint="finger_joint_1" multiplier="1" offset="0"></mimic>
	</joint>
	<joint name="right_inner_finger_joint_1" type="revolute">
		<origin rpy="0 0 0" xyz="0 0.0061 0.0471"></origin>
		<parent link="right_outer_finger_1"></parent>
		<child link="right_inner_finger_1"></child>
		<axis xyz="1 0 0"></axis>
		<limit effort="1000" lower="-0.8" upper="0" velocity="100.2"></limit>
		<mimic joint="finger_joint_1" multiplier="-1" offset="0"></mimic>
	</joint>
	<joint name="right_inner_finger_pad_joint_1" type="fixed">
		<origin rpy="0 0 0" xyz="0 -0.0190203446692936 0.03867"></origin>
		<parent link="right_inner_finger_1"></parent>
		<child link="right_inner_finger_pad_1"></child>
		<axis xyz="0 0 1"></axis>
	</joint>
	<joint name="dummy_center_fixed_joint_1" type="fixed">
		<parent link="robotiq_arg2f_base_link_1"></parent>
		<child link="dummy_center_indicator_link_1"></child>
		<origin xyz="0 0 0.1725"></origin>
	</joint>
</robot>